Workbook

Sheet Dossiê de Crédito
C2: DOSSIÊ DE VIABILIDADE E CRÉDITO | H2: ✔ APROVADO (76 PTS)
C4: MARCOS HENRIQUE ANDRADE DE MEDEIROS | 30 ANOS
D8: CAPACIDADE TOTAL DE COMPRA LIBERADA PARA NEGOCIAÇÃO
C14: DADOS DE CRÉDITO IA | H14: O SEU INVESTIMENTO HOJE
C16: CRÉDITO CAIXA: | E16: ='Fluxo Detalhado'!D27 | H16: Entrada Disponível / Acordada
C17: SUBSÍDIO (Governo): | E17: ='Fluxo Detalhado'!D29 | H17: ='Fluxo Detalhado'!C13
C18: SALDO FGTS: | E18: ='Fluxo Detalhado'!C14
C22: 💳 PLANO DE FLUXO DE PAGAMENTO (CONSTRUTORA + BANCO)
C24: ENQUADRAMENTO / ITBI | E24: ENTRADA PARCELADA (CONSTRUTORA) | G24: EVOLUÇÃO DE OBRA (MÉDIA) | I24: PRESTAÇÃO MENSAL (PÓS-CHAVES)
C25: ='Fluxo Detalhado'!D33 | E25: ='Fluxo Detalhado'!D31 | I25: ='Fluxo Detalhado'!D30
C27: ="ITBI " & 'Fluxo Detalhado'!D36 | E27: Período: 36 meses | G27: Conforme a obra avança | I27: Financiamento definitivo
D31: 📈 AUMENTO DE PATRIMÔNIO (PROJEÇÃO NA CHAVE)
C33: VALOR DO IMÓVEL (HOJE) | G33: VALOR NA ENTREGA (MÉDIA +30%)
G34: ='Dossiê de Crédito'!C34 * 1.30
C40: 🛡️ A BLINDAGEM 360° MT PARCEIROS
C42: 🏦 1. APROVAÇÃO BANCÁRIA Todo limite é analisado via API direto antes da emissão do contrato. | E42: ⚖️ 2. ANÁLISE JURÍDICA Nossos advogados validam a idoneidade e cláusulas perigosas. | G42: 🏗️ 3. ACOMPANHAMENTO Não abandonamos você. Nossa equipe acompanha as medições de obra. | I42: 👷 4. LAUDO DE ENGENHARIA Selo MT: O fechamento garante que nossa engenheira fará sua Vistoria Final.
C49: ESTE DOSSIÊ É ESTRITAMENTE CONFIDENCIAL E TEM FINS DE PLANEJAMENTO.

Sheet Fluxo Detalhado
A2: MT PARCEIROS · SIMULADOR INTELIGENTE DE CRÉDITO IMOBILIÁRIO | F2: 📍 mtparceiros@gmail.com | 📞 (11) 96036-4355 | 🌐 mtparceiros-alt.github.io
A5: 👤 IDENTIFICAÇÃO DO CLIENTE
B7: Nome do Cliente: | C7: Digite seu nome aqui... | F7: ← Preencha com o nome completo do cliente
B8: Data da Simulação: | C8: =TODAY() | F8: 🏥 Saúde Financeira: | G8: =IF(D28="","⏳ Aguardando dados...",IF(D28<=0.25,"🟢 EXCELENTE",IF(D28<=0.3,"🟡 BOA","🔴 ATENÇÃO")))
A10: 📥 DADOS DE ENTRADA — Preencha os campos destacados
B11: 1. RENDA E RECURSOS
B12: Renda Bruta Familiar (R$): | C12: 8000 | D12: =IFERROR(REPT("█",INT(MIN(20,C12/1000)),),"") | F12: ← Renda total do núcleo familiar
B13: Entrada em Dinheiro (R$): | C13: 15000 | D13: =IFERROR(REPT("█",INT(MIN(20,C13/2000)),),"") | F13: ← Dinheiro disponível para dar de entrada
B14: Saldo FGTS (R$): | C14: 30000 | D14: =IFERROR(REPT("█",INT(MIN(20,C14/2000)),),"") | F14: ← Consulte o app FGTS ou extrato
B15: Carteira Assinada (3+ anos)? | C15: SIM | F15: ← SIM = multiplica o crédito por fator 142x (vs 132x)
B16: 2. COMPROMETIMENTO MENSAL (Despesas)
B17: Aluguel Atual (R$): | C17: 1200 | D17: =IFERROR(REPT("█",INT(MIN(20,C17/500)),),"")
B18: Alimentação (R$): | C18: 800 | D18: =IFERROR(REPT("█",INT(MIN(20,C18/500)),),"")
B19: Transporte (R$): | C19: 400 | D19: =IFERROR(REPT("█",INT(MIN(20,C19/500)),),"")
B20: Outras Dívidas / Fixos (R$): | C20: 0 | D20: =IFERROR(REPT("█",INT(MIN(20,C20/500)),),"")
B21: Outros (R$): | C21: 0 | D21: =IFERROR(REPT("█",INT(MIN(20,C21/500)),),"")
B22: TOTAL DESPESAS MENSAIS: | C22: =IFERROR(SUM(C17:C21),0) | D22: =IFERROR(REPT("█",INT(MIN(20,C22/500))),"") | F22: =IFERROR(IF(C22/C12>0.3,"⚠️ Despesas superam 30% da renda — risco de reprovação","✅ Despesas dentro do limite de 30% da renda"),"")
A24: 📊 ANÁLISE DO FINANCIAMENTO CAIXA — calculado automaticamente
B25: 3. CÁLCULO DO CRÉDITO (MCMV 2025 — Regras Oficiais CAIXA)
B26: Faixa MCMV: | D26: =IFERROR(IF(C12<=2850,"FAIXA 1 — até R$ 2.850",IF(C12<=4700,"FAIXA 2 — até R$ 4.700","FAIXA 3 — até R$ 8.000")),"") | F26: ← Determinada automaticamente pela renda
B27: Seu Crédito CAIXA (Máximo): | D27: =IFERROR(ROUND(MAX(0,(C12*0.3-C22)*IF(C15="SIM",142,132)),0),0) | F27: (Renda × 30% − Despesas) × Fator de Crédito
B28: Comprometimento de Renda: | D28: =IFERROR(C28/C12,0) | F28: Parcela Projetada (R$): | H28: =IFERROR(MAX(0,(C12*0.3)-C22),0)
B29: Subsídio Federal (MCMV): | D29: =IFERROR(IF(C12<=2850,55000,IF(C12<=4700,35000,0)),0) | F29: =IFERROR(IF(C12<=2850,"Faixa 1: R$ 55.000",IF(C12<=4700,"Faixa 2: R$ 35.000","Não se aplica nesta faixa")),"")
B30: Subsídio Casa Paulista (SP): | D30: =IFERROR(IF(C12<=4863,16000,0),0) | F30: =IFERROR(IF(C12<=4863,"✅ R$ 16.000 — elegível","❌ Não elegível nesta faixa de renda"),"")
B32: 💰 PODER DE COMPRA TOTAL: | F32: =IFERROR(C27+C29+C30+C14+C13,0) | I32: Crédito + Subsídios + FGTS + Entrada
A34: 📋 LAUDO EXECUTIVO — gerado automaticamente pelo algoritmo IA
B35: Status da Análise: | D35: =IFERROR(IF(C28/C12<=0.3,"✅ APROVAÇÃO PROVÁVEL","⚠️ RISCO — Comprometimento acima de 30%"),"")
B36: =IFERROR("Simulação preparada para: "&D7,"Simulação preparada para: ---")
B37: RENDA FAMILIAR | D37: CRÉDITO CAIXA MÁX. | F37: PODER DE COMPRA | H37: PARCELA PROJETADA
B38: =IFERROR(C12,0) | D38: =IFERROR(C27,0) | F38: =IFERROR(C32,0) | H38: =IFERROR(H28,0)
B39: SALDO FGTS | D39: COMPROMETIMENTO | F39: SUBSÍDIO TOTAL | H39: MARGEM DE SEGURANÇA
B40: =IFERROR(C14,0) | D40: =IFERROR(C28/C12,0) | F40: =IFERROR(C29+C30,0) | H40: =IFERROR(1-(C28/C12),0)
B42: 4. SCORE DE JORNADA
B43: Pontuação de Aprovação: | D43: =IFERROR(MIN(100,MIN(40,MAX(0,40-((C28/C12-0.25)*200)))+MIN(30,C14/50000*30)+IF(C15="SIM",15,0)+MIN(15,(C13+C14)/5000)),0) | F43: =IFERROR(REPT("★",INT(H42/20))&REPT("☆",5-INT(H42/20)),"☆☆☆☆☆")
B44: =IFERROR("📍 Etapa atual: Simulação → Escolha do Imóvel → Documentação → Contrato → Assinatura","---")
A46: 🏠 ESCOLHA DO IMÓVEL
B47: 5. SELECIONE O IMÓVEL DESEJADO
B48: Imóvel Selecionado: | D48: Selecione um Imóvel... | H48: ← Clique e selecione da lista
B49: Valor Estimado (R$): | D49: =IFERROR(VLOOKUP(D48,SysData,2,FALSE()),0) | F49: =IFERROR(IF(VLOOKUP(D48,SysData,2,FALSE())<=C32,"✅ Dentro do seu poder de compra","⚠️ Acima do seu poder de compra"),"")
B50: Bairro / Localização: | D50: =IFERROR(VLOOKUP(D48,SysData,5,FALSE()),"---")
...
