Workbook

Sheet System Data
A1: 💡 IMPORTANTE: Esta tabela (Table_Empreendimentos) é a fonte de dados primária. Use "Atualizar Tudo" se conectada a fontes externas.
A3: ID | B3: Nome | C3: Preço | D3: Área | E3: Quartos | F3: Bairro | G3: Entrega | H3: Diferenciais | I3: Lazer | J3: Imagem_URL
A4: 1 | B4: Vivaz Penha 2 | C4: 205000 | D4: De 24m² a 38m² | E4: 1 a 2 | F4: Penha (Zona Leste) | G4: 205mil
A5: 2 | B5: Vivaz Freguesia do Ó | C5: 226000 | D5: De 24m² a 45m² | E5: 1 a 2 | F5: Freguesia (Zona Norte) | G5: 226mil
A6: 3 | B6: Vivaz Santo Amaro | C6: 218000 | D6: De 24m² a 40m² | E6: 2 a 2 | F6: Santo Amaro (Zona Sul) | G6: 218mil
A7: 4 | B7: Vivaz Estação Lapa | C7: 214000 | D7: De 24m² a 36m² | E7: 1 a 2 | F7: Lapa (Zona Oeste) | G7: 214mil
A8: 5 | B8: Grand Vivaz Penha | C8: 235000 | D8: De 24m² a 38m² | E8: 1 a 2 | F8: Penha (Zona Leste) | G8: 235mil
A9: 6 | B9: Grand Vivaz Estação Tamanduateí | C9: 217000 | D9: De 24m² a 36m² | E9: 1 a 2 | F9: Vila Prudente | G9: 217mil
A10: 7 | B10: Grand Vivaz Jardim França Paris | C10: 224000 | D10: De 24m² a 36m² | E10: 1 a 2 | F10: Jardim França | G10: 224mil
A11: 8 | B11: Vivaz Selection Santo Amaro | C11: 218000 | D11: De 24m² a 40m² | E11: 1 a 2 | F11: Santo Amaro | G11: 218mil
A12: 9 | B12: Vivaz Selection Laguna | C12: 235000 | D12: De 24m² a 36m² | E12: 1 a 2 | F12: Granja Julieta | G12: 235mil
A13: 10 | B13: Vivaz Estação Pirituba | C13: 235000 | D13: De 24m² a 36m² | E13: 1 a 2 | F13: Pirituba | G13: 235mil
A14: 11 | B14: Vivaz Parque João Dias | C14: 235000 | D14: De 24m² a 38m² | E14: 1 a 2 | F14: Santo Amaro | G14: 235mil
A15: 12 | B15: Vivaz Connection Adolfo Pinheiro | C15: 0.182 | D15: De 24m² a 36m² | E15: 1 a 2 | F15: Santo Amaro | G15: 244mil
... A23: 20 | B23: Vivaz Prime Vila Prudente | C23: 537000 | D23: De 48m² a 56m² | E23: 2 a 3 | F23: Vila Prudente | G23: 537mil
A28: Parâmetros Internos
A29: Renda_Base | B29: 8500
A30: FGTS_Base | B30: 30000
A31: Entrada_Base | B31: 15000
A32: Prazo_Meses | B32: 420

Sheet _BI_Export
A1: Data_Extracao | B1: ID_Simulacao | C1: Cliente_Renda | D1: Cliente_FGTS | E1: Cliente_PoderCompra | F1: Imovel_Nome | G1: VLR_Parcela
A2: =TODAY() -> 0 | B2: SIM-0001 | C2: ='Educação Financeira'!$E$13 -> 0 | D2: ='Educação Financeira'!$E$24 -> 0 | E2: ='Educação Financeira'!$E$31 -> 0 | F2: ='Educação Financeira'!$G$6 -> 0 | G2: ='Educação Financeira'!$E$33 -> 0

Sheet Início
C3: =HYPERLINK("#'Laudo de Crédito'!A1", "Laudo de Crédito") -> 0 | E3: =HYPERLINK("#'Educação Financeira'!A1", "Educação Financeira") -> 0 | G3: =HYPERLINK("#'Fluxo Mensal'!A1", "Fluxo Mensal") -> 0
B4: PORTAL MT PARCEIROS
C7: MT PARCEIROS
C11: BEM-VINDO À SUA ANÁLISE PERSONALIZADA
C13: 🤖 Esta ferramenta utiliza Inteligência Artificial para calcular seu potencial de compra imobiliária.
C15: ESTA ANÁLISE FOI PREPARADA COM TECNOLOGIA MT PARCEIROS Cálculos baseados nas regras oficiais da CAIXA (2025)
C19: COMO COMEÇAR:
C20: 1. Digite seu nome abaixo para personalizar o relatório.
C21: 2. Vá para as abas de análise para conferir seu potencial.
C23: SEU NOME: | E23: Digite seu nome aqui...
C26: INICIAR SIMULAÇÃO ▶
C29: ⚠️ Valores estimados para fins de consultoria. MT Parceiros | (11) 96036-4355
C34: MENSAIS DA ENTRADA | G34: EVOLUÇÃO OBRA | K34: PARCELA FINANCIAMENTO
C35: 0 | G35: 0 | K35: 0
C36: 36x (Parcelas) | G36: Média mensal | K36: Após a entrega (até 35 anos)
C40: Documentação Necessária
C41: Separe estes documentos para acelerar sua aprovação com a Caixa:
C43: RG e CPF | E43: Certidão de Estado Civil | G43: Comprovante de Renda (3 meses)
C45: Comprovante de Residência | E45: Extrato FGTS | G45: Declaração IRPF
C49: 💬 Iniciar Atendimento
B61: 🤖 Simulação gerada por Algoritmo de IA MT Parceiros • Gerado em 27/02/2026 • © MT Parceiros

Sheet Laudo de Crédito
B1: 📍 mtparceiros@gmail.com | 📞 (11) 96036-4355 | 🌐 mtparceiros-alt.github.io/site-mt
C3: =HYPERLINK("#'Laudo de Crédito'!A1", "Laudo de Crédito") -> 0 | E3: =HYPERLINK("#'Educação Financeira'!A1", "Educação Financeira") -> 0 | G3: =HYPERLINK("#'Fluxo Mensal'!A1", "Fluxo Mensal") -> 0
B4: PORTAL MT PARCEIROS
C6: 📊 ANÁLISE EXECUTIVA (Algoritmo IA) | I6: JORNADA: | J6: Simulação | K6: Contrato
C7: Laudo de Crédito
C8: Esta análise foi gerada por algoritmo proprietário MT Parceiros, com base nos parâmetros reais da CAIXA e regras MCMV 2025.
C10: ="Simulação preparada para: " & 'Educação Financeira'!C9 -> 0
C13: RENDA FAMILIAR | G13: PODER DE COMPRA TOTAL
C14: ='Educação Financeira'!E13 -> 0 | G14: ='Educação Financeira'!E31 -> 0
C17: CRÉDITO CAIXA MAX | G17: PARCELA PROJETADA
C18: ='Educação Financeira'!E29 -> 0 | G18: ='Educação Financeira'!E33 -> 0
C21: SUBSÍDIO ESTIMADO | G21: COMPROMETIMENTO
C22: ='Educação Financeira'!E30 -> 0 | G22: =('Educação Financeira'!E33 / 'Educação Financeira'!E13) -> 0
I24: Status da Análise:
C25: SALDO FGTS | I25: =IF('Educação Financeira'!E33/'Educação Financeira'!E13 <= 0.30, "Aprovação Provável", "Risco de Parcelamento") -> 0
C26: ='Educação Financeira'!E24 -> 0
C28: SEU SCORE MT PARCEIROS
C29: =MIN(100, MIN(40, MAX(0, 40-((('Educação Financeira'!E33/'Educação Financeira'!E13)-0.25)*200))) + MIN(30, 'Educação Financeira'!E24/50000*30) + IF('Educação Financeira'!E26="SIM",30,10)) -> 0
C33: 1. ANÁLISE DE COMPOSIÇÃO DE COMPRA | I33: 2. RISCO E SAÚDE FINANCEIRA
C35: Financiamento | E35: ='Educação Financeira'!E29 -> 0 | G35: =IF(E35>0, REPT("█", INT(MIN(20, E35/20000))), "") -> 0 | I35: Comprometimento:
I36: =IF(IFERROR('Educação Financeira'!E33 / 'Educação Financeira'!E13, 0)>0, REPT("▓", INT(MIN(30, IFERROR('Educação Financeira'!E33 / 'Educação Financeira'!E13, 0) * 100))), "") -> 0
C37: Subsídio Gov. | E37: ='Educação Financeira'!E30 -> 0 | G37: =IF(E37>0, REPT("█", INT(MIN(20, E37/5000))), "") -> 0
I38: Margem de Segurança:
C39: FGTS + Próprios | E39: ='Educação Financeira'!E24 -> 0 | G39: =IF(E39>0, REPT("█", INT(MIN(20, E39/5000))), "") -> 0 | I39: =IF(IFERROR(1 - ('Educação Financeira'!E33 / 'Educação Financeira'!E13), 0)>0, REPT("▓", INT(MIN(30, IFERROR(1 - ('Educação Financeira'!E33 / 'Educação Financeira'!E13), 0) * 100))), "") -> 0
B41: 🤖 Simulação gerada por Algoritmo de IA MT Parceiros • Gerado em 27/02/2026 • © MT Parceiros

Sheet Educação Financeira
B1: 📍 mtparceiros@gmail.com | 📞 (11) 96036-4355 | 🌐 mtparceiros-alt.github.io/site-mt | Z1: =IFERROR(VLOOKUP(G6,Table_Empreendimentos[[Nome]:[Preço]],2,FALSE),0) -> 0
Z2: ='System Data'!B4 -> 0
C3: =HYPERLINK("#'Laudo de Crédito'!A1", "Laudo de Crédito") -> 0 | E3: =HYPERLINK("#'Educação Financeira'!A1", "Educação Financeira") -> 0 | G3: =HYPERLINK("#'Fluxo Mensal'!A1", "Fluxo Mensal") -> 0 | Z3: ='System Data'!B5 -> 0
B4: PORTAL MT PARCEIROS | Z4: ='System Data'!B6 -> 0
Z5: ='System Data'!B7 -> 0
C6: 🧠 SIMULADOR INTELIGENTE (Algoritmo Oficial) | Z6: ='System Data'!B8 -> 0
C7: Educação Financeira | G7: IMÓVEL SELECIONADO: | Z7: ='System Data'!B9 -> 0
C8: NOME DO CLIENTE: | G8: Selecione um Imóvel... | Z8: ='System Data'!B10 -> 0
C9: ='Início'!E23 -> 0 | Z9: ='System Data'!B11 -> 0
C10: Nosso algoritmo aplica as regras oficiais da CAIXA para calcular seu crédito máximo e subsídio MCMV. | Z10: ='System Data'!B12 -> 0
Z11: ='System Data'!B13 -> 0
C12: 1. DADOS DE ENTRADA (Sua Renda) | Z12: ='System Data'!B14 -> 0
C13: Renda Bruta Familiar: | E13: 8000 | G13: =IF(E13>0, REPT("█", INT(MIN(20, E13/1000))), "") -> 0 | Z13: ='System Data'!B15 -> 0
Z14: ='System Data'!B16 -> 0
C15: 2. COMPROMETIMENTO (Despesas) | Z15: ='System Data'!B17 -> 0
Z16: ='System Data'!B18 -> 0
C17: Aluguel Atual | E17: 1200 | G17: =IF(E17>0, REPT("█", INT(MIN(20, E17/500))), "") -> 0 | Z17: ='System Data'!B19 -> 0
C18: Alimentação | E18: 800 | G18: =IF(E18>0, REPT("█", INT(MIN(20, E18/500))), "") -> 0 | Z18: ='System Data'!B20 -> 0
C19: Transporte | E19: 400 | G19: =IF(E19>0, REPT("█", INT(MIN(20, E19/500))), "") -> 0 | Z19: ='System Data'!B21 -> 0
C20: Outros | E20: 0 | G20: =IF(E20>0, REPT("█", INT(MIN(20, E20/500))), "") -> 0 | Z20: ='System Data'!B22 -> 0
Z21: ='System Data'!B23 -> 0
C22: TOTAL DESPESAS: | E22: =SUM(E17:E21) -> 0 | Z22: ='System Data'!B24 -> 0
C24: SALDO FGTS: | E24: 30000 | G24: =IF(E24>0, REPT("█", INT(MIN(20, E24/2000))), "") -> 0
C26: TEM CARTEIRA (3+ ANOS)? | E26: SIM
C28: 3. ANÁLISE DO FINANCIAMENTO (MCMV)
C29: Seu Crédito CAIXA (Max): | E29: =MAX(0, (E13*0.30)*150) -> 0 | G29: =IF(E22/E13 > 0.4, "⚠️ ALERTA: Comprometimento Alto", "✅ SAUDÁVEL: Perfil Positivo") -> 0
C30: Subsídio MCMV Estimado: | E30: =IF(E13<=2640, 55000, IF(E13<=4400, 35000, 0)) -> 0
C31: PODER DE COMPRA TOTAL: | E31: =E29 + E30 + E24 -> 0
C33: PARCELA PROJETADA (Fixa): | E33: =E13 * 0.28 -> 0
B41: 🤖 Simulação gerada por Algoritmo de IA MT Parceiros • Gerado em 27/02/2026 • © MT Parceiros

Sheet Fluxo Mensal
B1: 📍 mtparceiros@gmail.com | 📞 (11) 96036-4355 | 🌐 mtparceiros-alt.github.io/site-mt
C3: =HYPERLINK("#'Laudo de Crédito'!A1", "Laudo de Crédito") -> 0 | E3: =HYPERLINK("#'Educação Financeira'!A1", "Educação Financeira") -> 0 | G3: =HYPERLINK("#'Fluxo Mensal'!A1", "Fluxo Mensal") -> 0
B4: PORTAL MT PARCEIROS
C6: 📅 PROJEÇÃO FINANCEIRA REAL E CONTROLE
C7: Fluxo Acumulado e Tracker de Aportes
D8: ="Plano Mensal para: " & 'Início'!C22 -> 0
C9: 💰 TOTAL APORTADO (Real) | F9: ⏳ SALDO DEVEDOR (Restante)
C10: =SUMIF(B13:B100, "Sim", D13:D100) + SUMIF(B13:B100, "Sim", E13:E100) -> 0 | F10: =('Educação Financeira'!E31) - (SUMIF(B13:B100, "Sim", D13:D100) + SUMIF(B13:B100, "Sim", E13:E100)) -> 0
B12: ✅ Pago? | C12: Mês / Ano | D12: Aporte Mensal | E12: Extra (Throughput) | F12: Saldo Acumulado | G12: Referência Meta | H12: Status
B13: Não | C13: =EDATE(TODAY(), 0) -> 0 | D13: =MAX(0, 'Educação Financeira'!$E$33 * 0.5) -> 0 | E13: =IF(MONTH(C13)=12, 'Educação Financeira'!$E$13 * 0.5, 0) -> 0 | F13: ='Educação Financeira'!$E$24 + IF(B13="Sim", D13 + E13, 0) -> 0 | G13: =('Educação Financeira'!E31) -> 0 | H13: =IF(F13>=G13, "✅ ATINGIDA", "⏳ EM CURSO") -> 0
B14: Não | C14: =EDATE(TODAY(), 1) -> 0 | D14: =MAX(0, 'Educação Financeira'!$E$33 * 0.5) -> 0 | E14: =IF(MONTH(C14)=12, 'Educação Financeira'!$E$13 * 0.5, 0) -> 0 | F14: =F13 + IF(B14="Sim", D14 + E14, 0) -> 0 | G14: =('Educação Financeira'!E31) -> 0 | H14: =IF(F14>=G14, "✅ ATINGIDA", "⏳ EM CURSO") -> 0
B15: Não | C15: =EDATE(TODAY(), 2) -> 0 | D15: =MAX(0, 'Educação Financeira'!$E$33 * 0.5) -> 0 | E15: =IF(MONTH(C15)=12, 'Educação Financeira'!$E$13 * 0.5, 0) -> 0 | F15: =F14 + IF(B15="Sim", D15 + E15, 0) -> 0 | G15: =('Educação Financeira'!E31) -> 0 | H15: =IF(F15>=G15, "✅ ATINGIDA", "⏳ EM CURSO") -> 0
B16: Não | C16: =EDATE(TODAY(), 3) -> 0 | D16: =MAX(0, 'Educação Financeira'!$E$33 * 0.5) -> 0 | E16: =IF(MONTH(C16)=12, 'Educação Financeira'!$E$13 * 0.5, 0) -> 0 | F16: =F15 + IF(B16="Sim", D16 + E16, 0) -> 0 | G16: =('Educação Financeira'!E31) -> 0 | H16: =IF(F16>=G16, "✅ ATINGIDA", "⏳ EM CURSO") -> 0
B17: Não | C17: =EDATE(TODAY(), 4) -> 0 | D17: =MAX(0, 'Educação Financeira'!$E$33 * 0.5) -> 0 | E17: =IF(MONTH(C17)=12, 'Educação Financeira'!$E$13 * 0.5, 0) -> 0 | F17: =F16 + IF(B17="Sim", D17 + E17, 0) -> 0 | G17: =('Educação Financeira'!E31) -> 0 | H17: =IF(F17>=G17, "✅ ATINGIDA", "⏳ EM CURSO") -> 0
B18: Não | C18: =EDATE(TODAY(), 5) -> 0 | D18: =MAX(0, 'Educação Financeira'!$E$33 * 0.5) -> 0 | E18: =IF(MONTH(C18)=12, 'Educação Financeira'!$E$13 * 0.5, 0) -> 0 | F18: =F17 + IF(B18="Sim", D18 + E18, 0) -> 0 | G18: =('Educação Financeira'!E31) -> 0 | H18: =IF(F18>=G18, "✅ ATINGIDA", "⏳ EM CURSO") -> 0
B19: Não | C19: =EDATE(TODAY(), 6) -> 0 | D19: =MAX(0, 'Educação Financeira'!$E$33 * 0.5) -> 0 | E19: =IF(MONTH(C19)=12, 'Educação Financeira'!$E$13 * 0.5, 0) -> 0 | F19: =F18 + IF(B19="Sim", D19 + E19, 0) -> 0 | G19: =('Educação Financeira'!E31) -> 0 | H19: =IF(F19>=G19, "✅ ATINGIDA", "⏳ EM CURSO") -> 0
B20: Não | C20: =EDATE(TODAY(), 7) -> 0 | D20: =MAX(0, 'Educação Financeira'!$E$33 * 0.5) -> 0 | E20: =IF(MONTH(C20)=12, 'Educação Financeira'!$E$13 * 0.5, 0) -> 0 | F20: =F19 + IF(B20="Sim", D20 + E20, 0) -> 0 | G20: =('Educação Financeira'!E31) -> 0 | H20: =IF(F20>=G20, "✅ ATINGIDA", "⏳ EM CURSO") -> 0
B21: Não | C21: =EDATE(TODAY(), 8) -> 0 | D21: =MAX(0, 'Educação Financeira'!$E$33 * 0.5) -> 0 | E21: =IF(MONTH(C21)=12, 'Educação Financeira'!$E$13 * 0.5, 0) -> 0 | F21: =F20 + IF(B21="Sim", D21 + E21, 0) -> 0 | G21: =('Educação Financeira'!E31) -> 0 | H21: =IF(F21>=G21, "✅ ATINGIDA", "⏳ EM CURSO") -> 0
B22: Não | C22: =EDATE(TODAY(), 9) -> 0 | D22: =MAX(0, 'Educação Financeira'!$E$33 * 0.5) -> 0 | E22: =IF(MONTH(C22)=12, 'Educação Financeira'!$E$13 * 0.5, 0) -> 0 | F22: =F21 + IF(B22="Sim", D22 + E22, 0) -> 0 | G22: =('Educação Financeira'!E31) -> 0 | H22: =IF(F22>=G22, "✅ ATINGIDA", "⏳ EM CURSO") -> 0
B23: Não | C23: =EDATE(TODAY(), 10) -> 0 | D23: =MAX(0, 'Educação Financeira'!$E$33 * 0.5) -> 0 | E23: =IF(MONTH(C23)=12, 'Educação Financeira'!$E$13 * 0.5, 0) -> 0 | F23: =F22 + IF(B23="Sim", D23 + E23, 0) -> 0 | G23: =('Educação Financeira'!E31) -> 0 | H23: =IF(F23>=G23, "✅ ATINGIDA", "⏳ EM CURSO") -> 0
B24: Não | C24: =EDATE(TODAY(), 11) -> 0 | D24: =MAX(0, 'Educação Financeira'!$E$33 * 0.5) -> 0 | E24: =IF(MONTH(C24)=12, 'Educação Financeira'!$E$13 * 0.5, 0) -> 0 | F24: =F23 + IF(B24="Sim", D24 + E24, 0) -> 0 | G24: =('Educação Financeira'!E31) -> 0 | H24: =IF(F24>=G24, "✅ ATINGIDA", "⏳ EM CURSO") -> 0
B25: Não | C25: =EDATE(TODAY(), 12) -> 0 | D25: =MAX(0, 'Educação Financeira'!$E$33 * 0.5) -> 0 | E25: =IF(MONTH(C25)=12, 'Educação Financeira'!$E$13 * 0.5, 0) -> 0 | F25: =F24 + IF(B25="Sim", D25 + E25, 0) -> 0 | G25: =('Educação Financeira'!E31) -> 0 | H25: =IF(F25>=G25, "✅ ATINGIDA", "⏳ EM CURSO") -> 0
B26: Não | C26: =EDATE(TODAY(), 13) -> 0 | D26: =MAX(0, 'Educação Financeira'!$E$33 * 0.5) -> 0 | E26: =IF(MONTH(C26)=12, 'Educação Financeira'!$E$13 * 0.5, 0) -> 0 | F26: =F25 + IF(B26="Sim", D26 + E26, 0) -> 0 | G26: =('Educação Financeira'!E31) -> 0 | H26: =IF(F26>=G26, "✅ ATINGIDA", "⏳ EM CURSO") -> 0
B27: Não | C27: =EDATE(TODAY(), 14) -> 0 | D27: =MAX(0, 'Educação Financeira'!$E$33 * 0.5) -> 0 | E27: =IF(MONTH(C27)=12, 'Educação Financeira'!$E$13 * 0.5, 0) -> 0 | F27: =F26 + IF(B27="Sim", D27 + E27, 0) -> 0 | G27: =('Educação Financeira'!E31) -> 0 | H27: =IF(F27>=G27, "✅ ATINGIDA", "⏳ EM CURSO") -> 0
B28: Não | C28: =EDATE(TODAY(), 15) -> 0 | D28: =MAX(0, 'Educação Financeira'!$E$33 * 0.5) -> 0 | E28: =IF(MONTH(C28)=12, 'Educação Financeira'!$E$13 * 0.5, 0) -> 0 | F28: =F27 + IF(B28="Sim", D28 + E28, 0) -> 0 | G28: =('Educação Financeira'!E31) -> 0 | H28: =IF(F28>=G28, "✅ ATINGIDA", "⏳ EM CURSO") -> 0
B29: Não | C29: =EDATE(TODAY(), 16) -> 0 | D29: =MAX(0, 'Educação Financeira'!$E$33 * 0.5) -> 0 | E29: =IF(MONTH(C29)=12, 'Educação Financeira'!$E$13 * 0.5, 0) -> 0 | F29: =F28 + IF(B29="Sim", D29 + E29, 0) -> 0 | G29: =('Educação Financeira'!E31) -> 0 | H29: =IF(F29>=G29, "✅ ATINGIDA", "⏳ EM CURSO") -> 0
B30: Não | C30: =EDATE(TODAY(), 17) -> 0 | D30: =MAX(0, 'Educação Financeira'!$E$33 * 0.5) -> 0 | E30: =IF(MONTH(C30)=12, 'Educação Financeira'!$E$13 * 0.5, 0) -> 0 | F30: =F29 + IF(B30="Sim", D30 + E30, 0) -> 0 | G30: =('Educação Financeira'!E31) -> 0 | H30: =IF(F30>=G30, "✅ ATINGIDA", "⏳ EM CURSO") -> 0
B31: Não | C31: =EDATE(TODAY(), 18) -> 0 | D31: =MAX(0, 'Educação Financeira'!$E$33 * 0.5) -> 0 | E31: =IF(MONTH(C31)=12, 'Educação Financeira'!$E$13 * 0.5, 0) -> 0 | F31: =F30 + IF(B31="Sim", D31 + E31, 0) -> 0 | G31: =('Educação Financeira'!E31) -> 0 | H31: =IF(F31>=G31, "✅ ATINGIDA", "⏳ EM CURSO") -> 0
B32: Não | C32: =EDATE(TODAY(), 19) -> 0 | D32: =MAX(0, 'Educação Financeira'!$E$33 * 0.5) -> 0 | E32: =IF(MONTH(C32)=12, 'Educação Financeira'!$E$13 * 0.5, 0) -> 0 | F32: =F31 + IF(B32="Sim", D32 + E32, 0) -> 0 | G32: =('Educação Financeira'!E31) -> 0 | H32: =IF(F32>=G32, "✅ ATINGIDA", "⏳ EM CURSO") -> 0
B33: Não | C33: =EDATE(TODAY(), 20) -> 0 | D33: =MAX(0, 'Educação Financeira'!$E$33 * 0.5) -> 0 | E33: =IF(MONTH(C33)=12, 'Educação Financeira'!$E$13 * 0.5, 0) -> 0 | F33: =F32 + IF(B33="Sim", D33 + E33, 0) -> 0 | G33: =('Educação Financeira'!E31) -> 0 | H33: =IF(F33>=G33, "✅ ATINGIDA", "⏳ EM CURSO") -> 0
B34: Não | C34: =EDATE(TODAY(), 21) -> 0 | D34: =MAX(0, 'Educação Financeira'!$E$33 * 0.5) -> 0 | E34: =IF(MONTH(C34)=12, 'Educação Financeira'!$E$13 * 0.5, 0) -> 0 | F34: =F33 + IF(B34="Sim", D34 + E34, 0) -> 0 | G34: =('Educação Financeira'!E31) -> 0 | H34: =IF(F34>=G34, "✅ ATINGIDA", "⏳ EM CURSO") -> 0
B35: Não | C35: =EDATE(TODAY(), 22) -> 0 | D35: =MAX(0, 'Educação Financeira'!$E$33 * 0.5) -> 0 | E35: =IF(MONTH(C35)=12, 'Educação Financeira'!$E$13 * 0.5, 0) -> 0 | F35: =F34 + IF(B35="Sim", D35 + E35, 0) -> 0 | G35: =('Educação Financeira'!E31) -> 0 | H35: =IF(F35>=G35, "✅ ATINGIDA", "⏳ EM CURSO") -> 0
B36: Não | C36: =EDATE(TODAY(), 23) -> 0 | D36: =MAX(0, 'Educação Financeira'!$E$33 * 0.5) -> 0 | E36: =IF(MONTH(C36)=12, 'Educação Financeira'!$E$13 * 0.5, 0) -> 0 | F36: =F35 + IF(B36="Sim", D36 + E36, 0) -> 0 | G36: =('Educação Financeira'!E31) -> 0 | H36: =IF(F36>=G36, "✅ ATINGIDA", "⏳ EM CURSO") -> 0
B37: Não | C37: =EDATE(TODAY(), 24) -> 0 | D37: =MAX(0, 'Educação Financeira'!$E$33 * 0.5) -> 0 | E37: =IF(MONTH(C37)=12, 'Educação Financeira'!$E$13 * 0.5, 0) -> 0 | F37: =F36 + IF(B37="Sim", D37 + E37, 0) -> 0 | G37: =('Educação Financeira'!E31) -> 0 | H37: =IF(F37>=G37, "✅ ATINGIDA", "⏳ EM CURSO") -> 0
B38: Não | C38: =EDATE(TODAY(), 25) -> 0 | D38: =MAX(0, 'Educação Financeira'!$E$33 * 0.5) -> 0 | E38: =IF(MONTH(C38)=12, 'Educação Financeira'!$E$13 * 0.5, 0) -> 0 | F38: =F37 + IF(B38="Sim", D38 + E38, 0) -> 0 | G38: =('Educação Financeira'!E31) -> 0 | H38: =IF(F38>=G38, "✅ ATINGIDA", "⏳ EM CURSO") -> 0
B39: Não | C39: =EDATE(TODAY(), 26) -> 0 | D39: =MAX(0, 'Educação Financeira'!$E$33 * 0.5) -> 0 | E39: =IF(MONTH(C39)=12, 'Educação Financeira'!$E$13 * 0.5, 0) -> 0 | F39: =F38 + IF(B39="Sim", D39 + E39, 0) -> 0 | G39: =('Educação Financeira'!E31) -> 0 | H39: =IF(F39>=G39, "✅ ATINGIDA", "⏳ EM CURSO") -> 0
B40: Não | C40: =EDATE(TODAY(), 27) -> 0 | D40: =MAX(0, 'Educação Financeira'!$E$33 * 0.5) -> 0 | E40: =IF(MONTH(C40)=12, 'Educação Financeira'!$E$13 * 0.5, 0) -> 0 | F40: =F39 + IF(B40="Sim", D40 + E40, 0) -> 0 | G40: =('Educação Financeira'!E31) -> 0 | H40: =IF(F40>=G40, "✅ ATINGIDA", "⏳ EM CURSO") -> 0
B41: Não | C41: =EDATE(TODAY(), 28) -> 0 | D41: =MAX(0, 'Educação Financeira'!$E$33 * 0.5) -> 0 | E41: =IF(MONTH(C41)=12, 'Educação Financeira'!$E$13 * 0.5, 0) -> 0 | F41: =F40 + IF(B41="Sim", D41 + E41, 0) -> 0 | G41: =('Educação Financeira'!E31) -> 0 | H41: =IF(F41>=G41, "✅ ATINGIDA", "⏳ EM CURSO") -> 0
B42: Não | C42: =EDATE(TODAY(), 29) -> 0 | D42: =MAX(0, 'Educação Financeira'!$E$33 * 0.5) -> 0 | E42: =IF(MONTH(C42)=12, 'Educação Financeira'!$E$13 * 0.5, 0) -> 0 | F42: =F41 + IF(B42="Sim", D42 + E42, 0) -> 0 | G42: =('Educação Financeira'!E31) -> 0 | H42: =IF(F42>=G42, "✅ ATINGIDA", "⏳ EM CURSO") -> 0
B43: Não | C43: =EDATE(TODAY(), 30) -> 0 | D43: =MAX(0, 'Educação Financeira'!$E$33 * 0.5) -> 0 | E43: =IF(MONTH(C43)=12, 'Educação Financeira'!$E$13 * 0.5, 0) -> 0 | F43: =F42 + IF(B43="Sim", D43 + E43, 0) -> 0 | G43: =('Educação Financeira'!E31) -> 0 | H43: =IF(F43>=G43, "✅ ATINGIDA", "⏳ EM CURSO") -> 0
...

Sheet Kanban
A2: GESTÃO DE CLIENTE - BOARD KANBAN
A5: Tarefa / Documento | B5: Responsável | C5: Concluído? | D5: 📅 Prazo | E5: Obs
A6: 1. RG e CPF do Cliente | B6: Cliente | C6: FALSE
A7: 2. Certidão Estado Civil | B7: Cliente | C7: FALSE
A8: 3. Comprovantes de Renda | B8: Cliente | C8: FALSE
A9: 4. Comprovante Residência | B9: Cliente | C9: FALSE
A10: 5. Extrato FGTS | B10: Cliente | C10: FALSE
A11: 6. Declaração IRPF | B11: Cliente | C11: FALSE
A12: 7. Formulário CAIXA | B12: Corretor | C12: FALSE
A13: 8. Protocolo CEV | B13: Correspondente | C13: FALSE
